<?xml version="1.0" ?>
<robot name="robot" xmlns:xacro="http://www.ros.org/wiki/xacro">

<xacro:include filename="$(find robot_description)/urdf/materials.xacro" />
<xacro:include filename="$(find robot_description)/urdf/robot.trans" />
<xacro:include filename="$(find robot_description)/urdf/robot.gazebo" />
<link name="base_link">
  <inertial>
    <origin rpy="0 0 0" xyz="-0.019902403741442462 -0.026131815850244072 0.02238118207502583"/>
    <mass value="0.7310055412327093"/>
    <inertia ixx="0.000985" ixy="0.0" ixz="2.7e-05" iyy="0.001061" iyz="-4e-06" izz="0.001604"/>
  </inertial>
  <visual>
    <origin rpy="0 0 0" xyz="0 0 0"/>
    <geometry>
      <mesh filename="package://robot_description/meshes/base_link.stl" scale="0.001 0.001 0.001"/>
    </geometry>
    <material name="silver"/>
  </visual>
  <collision>
    <origin rpy="0 0 0" xyz="0 0 0"/>
    <geometry>
      <mesh filename="package://robot_description/meshes/base_link.stl" scale="0.001 0.001 0.001"/>
    </geometry>
  </collision>
</link>

<link name="WAIST_1">
  <inertial>
    <origin rpy="0 0 0" xyz="0.0022441628498335066 0.007590344465981981 0.01877031829177992"/>
    <mass value="0.5674790951447787"/>
    <inertia ixx="0.000389" ixy="-1.2e-05" ixz="-5e-05" iyy="0.00049" iyz="-5.3e-05" izz="0.000447"/>
  </inertial>
  <visual>
    <origin rpy="0 0 0" xyz="0.019548 0.026486 -0.056"/>
    <geometry>
      <mesh filename="package://robot_description/meshes/WAIST_1.stl" scale="0.001 0.001 0.001"/>
    </geometry>
    <material name="silver"/>
  </visual>
  <collision>
    <origin rpy="0 0 0" xyz="0.019548 0.026486 -0.056"/>
    <geometry>
      <mesh filename="package://robot_description/meshes/WAIST_1.stl" scale="0.001 0.001 0.001"/>
    </geometry>
  </collision>
</link>

<link name="ARM_1_1">
  <inertial>
    <origin rpy="0 0 0" xyz="0.04849048815110292 -0.008282958375380033 0.034105993344051316"/>
    <mass value="0.4435773528478237"/>
    <inertia ixx="0.000286" ixy="1e-06" ixz="-0.00033" iyy="0.000787" iyz="0.0" izz="0.000536"/>
  </inertial>
  <visual>
    <origin rpy="0 0 0" xyz="0.005629 0.022537 -0.096277"/>
    <geometry>
      <mesh filename="package://robot_description/meshes/ARM_1_1.stl" scale="0.001 0.001 0.001"/>
    </geometry>
    <material name="silver"/>
  </visual>
  <collision>
    <origin rpy="0 0 0" xyz="0.005629 0.022537 -0.096277"/>
    <geometry>
      <mesh filename="package://robot_description/meshes/ARM_1_1.stl" scale="0.001 0.001 0.001"/>
    </geometry>
  </collision>
</link>

<link name="ARM_2_1">
  <inertial>
    <origin rpy="0 0 0" xyz="0.031227914013118252 0.009778981953459175 0.021821434108410226"/>
    <mass value="0.4469758277074998"/>
    <inertia ixx="0.000222" ixy="-6e-06" ixz="-0.000194" iyy="0.000527" iyz="-4e-06" izz="0.000364"/>
  </inertial>
  <visual>
    <origin rpy="0 0 0" xyz="-0.092669 0.022537 -0.165106"/>
    <geometry>
      <mesh filename="package://robot_description/meshes/ARM_2_1.stl" scale="0.001 0.001 0.001"/>
    </geometry>
    <material name="silver"/>
  </visual>
  <collision>
    <origin rpy="0 0 0" xyz="-0.092669 0.022537 -0.165106"/>
    <geometry>
      <mesh filename="package://robot_description/meshes/ARM_2_1.stl" scale="0.001 0.001 0.001"/>
    </geometry>
  </collision>
</link>

<link name="ARM_3_1">
  <inertial>
    <origin rpy="0 0 0" xyz="0.0178644426794467 0.0057853932401775035 0.006331837612079949"/>
    <mass value="0.1425119969472937"/>
    <inertia ixx="2.6e-05" ixy="-4e-06" ixz="-5e-06" iyy="4.2e-05" iyz="-3e-06" izz="3e-05"/>
  </inertial>
  <visual>
    <origin rpy="0 0 0" xyz="-0.169228 0.013037 -0.212243"/>
    <geometry>
      <mesh filename="package://robot_description/meshes/ARM_3_1.stl" scale="0.001 0.001 0.001"/>
    </geometry>
    <material name="silver"/>
  </visual>
  <collision>
    <origin rpy="0 0 0" xyz="-0.169228 0.013037 -0.212243"/>
    <geometry>
      <mesh filename="package://robot_description/meshes/ARM_3_1.stl" scale="0.001 0.001 0.001"/>
    </geometry>
  </collision>
</link>

<link name="Gripper_base_v1_1">
  <inertial>
    <origin rpy="0 0 0" xyz="0.017487742153690977 0.0069768374118511865 0.016813346512586036"/>
    <mass value="0.12341304164534105"/>
    <inertia ixx="4e-05" ixy="-8e-06" ixz="-2.4e-05" iyy="5.7e-05" iyz="-8e-06" izz="4.4e-05"/>
  </inertial>
  <visual>
    <origin rpy="0 0 0" xyz="-0.195032 -0.002963 -0.224207"/>
    <geometry>
      <mesh filename="package://robot_description/meshes/Gripper_base_v1_1.stl" scale="0.001 0.001 0.001"/>
    </geometry>
    <material name="silver"/>
  </visual>
  <collision>
    <origin rpy="0 0 0" xyz="-0.195032 -0.002963 -0.224207"/>
    <geometry>
      <mesh filename="package://robot_description/meshes/Gripper_base_v1_1.stl" scale="0.001 0.001 0.001"/>
    </geometry>
  </collision>
</link>

<link name="gear2_v1_1">
  <inertial>
    <origin rpy="0 0 0" xyz="0.0035940850207041297 0.0020799037777591914 0.004383993365053629"/>
    <mass value="0.020141998404349198"/>
    <inertia ixx="2e-06" ixy="-1e-06" ixz="-1e-06" iyy="2e-06" iyz="-0.0" izz="3e-06"/>
  </inertial>
  <visual>
    <origin rpy="0 0 0" xyz="-0.220941 -0.025863 -0.255332"/>
    <geometry>
      <mesh filename="package://robot_description/meshes/gear2_v1_1.stl" scale="0.001 0.001 0.001"/>
    </geometry>
    <material name="silver"/>
  </visual>
  <collision>
    <origin rpy="0 0 0" xyz="-0.220941 -0.025863 -0.255332"/>
    <geometry>
      <mesh filename="package://robot_description/meshes/gear2_v1_1.stl" scale="0.001 0.001 0.001"/>
    </geometry>
  </collision>
</link>

<link name="gear1_v1_1">
  <inertial>
    <origin rpy="0 0 0" xyz="0.003510771238991073 -0.0020873383753472795 0.004335892130754415"/>
    <mass value="0.020736664284343446"/>
    <inertia ixx="2e-06" ixy="1e-06" ixz="-1e-06" iyy="2e-06" iyz="0.0" izz="3e-06"/>
  </inertial>
  <visual>
    <origin rpy="0 0 0" xyz="-0.220941 0.001037 -0.255332"/>
    <geometry>
      <mesh filename="package://robot_description/meshes/gear1_v1_1.stl" scale="0.001 0.001 0.001"/>
    </geometry>
    <material name="silver"/>
  </visual>
  <collision>
    <origin rpy="0 0 0" xyz="-0.220941 0.001037 -0.255332"/>
    <geometry>
      <mesh filename="package://robot_description/meshes/gear1_v1_1.stl" scale="0.001 0.001 0.001"/>
    </geometry>
  </collision>
</link>

<link name="Gripper_1_v1__1__1">
  <inertial>
    <origin rpy="0 0 0" xyz="0.018420173952665236 0.01343885600563166 0.015542185686239052"/>
    <mass value="0.04236978910676513"/>
    <inertia ixx="7e-06" ixy="-5e-06" ixz="-4e-06" iyy="9e-06" iyz="-3e-06" izz="1.1e-05"/>
  </inertial>
  <visual>
    <origin rpy="0 0 0" xyz="-0.242563 -0.040062 -0.272434"/>
    <geometry>
      <mesh filename="package://robot_description/meshes/Gripper_1_v1__1__1.stl" scale="0.001 0.001 0.001"/>
    </geometry>
    <material name="silver"/>
  </visual>
  <collision>
    <origin rpy="0 0 0" xyz="-0.242563 -0.040062 -0.272434"/>
    <geometry>
      <mesh filename="package://robot_description/meshes/Gripper_1_v1__1__1.stl" scale="0.001 0.001 0.001"/>
    </geometry>
  </collision>
</link>

<link name="Gripper_1_v1_1">
  <inertial>
    <origin rpy="0 0 0" xyz="0.021284737250215957 -0.00357315022855555 0.01719611089784917"/>
    <mass value="0.04236978910676513"/>
    <inertia ixx="4e-06" ixy="2e-06" ixz="-5e-06" iyy="1.3e-05" iyz="1e-06" izz="1e-05"/>
  </inertial>
  <visual>
    <origin rpy="0 0 0" xyz="-0.242454 0.015473 -0.272371"/>
    <geometry>
      <mesh filename="package://robot_description/meshes/Gripper_1_v1_1.stl" scale="0.001 0.001 0.001"/>
    </geometry>
    <material name="silver"/>
  </visual>
  <collision>
    <origin rpy="0 0 0" xyz="-0.242454 0.015473 -0.272371"/>
    <geometry>
      <mesh filename="package://robot_description/meshes/Gripper_1_v1_1.stl" scale="0.001 0.001 0.001"/>
    </geometry>
  </collision>
</link>

<joint name="Rev1" type="continuous">
  <origin rpy="0 0 0" xyz="-0.019548 -0.026486 0.056"/>
  <parent link="base_link"/>
  <child link="WAIST_1"/>
  <axis xyz="0.0 -0.0 1.0"/>
</joint>

<joint name="Rev2" type="revolute">
  <origin rpy="0 0 0" xyz="0.013919 0.003949 0.040277"/>
  <parent link="WAIST_1"/>
  <child link="ARM_1_1"/>
  <axis xyz="0.0 -1.0 -0.0"/>
  <limit effort="100" lower="-0.698132" upper="2.356194" velocity="100"/>
</joint>

<joint name="Rev3" type="revolute">
  <origin rpy="0 0 0" xyz="0.098298 0.0 0.068829"/>
  <parent link="ARM_1_1"/>
  <child link="ARM_2_1"/>
  <axis xyz="-0.0 1.0 0.0"/>
  <limit effort="100" lower="-1.22173" upper="1.48353" velocity="100"/>
</joint>

<joint name="Rev4" type="continuous">
  <origin rpy="0 0 0" xyz="0.076559 0.0095 0.047137"/>
  <parent link="ARM_2_1"/>
  <child link="ARM_3_1"/>
  <axis xyz="0.819152 0.0 0.573576"/>
</joint>

<joint name="Rev30" type="revolute">
  <origin rpy="0 0 0" xyz="0.025804 0.016 0.011964"/>
  <parent link="ARM_3_1"/>
  <child link="Gripper_base_v1_1"/>
  <axis xyz="0.0 1.0 0.0"/>
  <limit effort="100" lower="-1.396263" upper="1.832596" velocity="100"/>
</joint>

<joint name="Rev31" type="revolute">
  <origin rpy="0 0 0" xyz="0.025909 0.0229 0.031125"/>
  <parent link="Gripper_base_v1_1"/>
  <child link="gear2_v1_1"/>
  <axis xyz="-0.5 -0.0 0.866025"/>
  <limit effort="100" lower="-0.349066" upper="0.349066" velocity="100"/>
</joint>

<joint name="Rev32" type="revolute">
  <origin rpy="0 0 0" xyz="0.025909 -0.004 0.031125"/>
  <parent link="Gripper_base_v1_1"/>
  <child link="gear1_v1_1"/>
  <axis xyz="-0.5 -0.0 0.866025"/>
  <limit effort="100" lower="-0.349066" upper="0.349066" velocity="100"/>
</joint>

<joint name="Rigid33" type="fixed">
  <origin rpy="0 0 0" xyz="0.021622 0.014199 0.017102"/>
  <parent link="gear2_v1_1"/>
  <child link="Gripper_1_v1__1__1"/>
</joint>

<joint name="Rigid34" type="fixed">
  <origin rpy="0 0 0" xyz="0.021513 -0.014436 0.017039"/>
  <parent link="gear1_v1_1"/>
  <child link="Gripper_1_v1_1"/>
</joint>

</robot>
